[2021-09-03 03:21:03,855] {processor.py:162} INFO - Started process (PID=179) to work on /usr/local/airflow/dags/__pycache__/mssqlToCSV.py
[2021-09-03 03:21:03,856] {processor.py:613} INFO - Processing file /usr/local/airflow/dags/__pycache__/mssqlToCSV.py for tasks to queue
[2021-09-03 03:21:03,857] {logging_mixin.py:109} INFO - [2021-09-03 03:21:03,856] {dagbag.py:496} INFO - Filling up the DagBag from /usr/local/airflow/dags/__pycache__/mssqlToCSV.py
[2021-09-03 03:21:03,876] {processor.py:623} INFO - DAG(s) dict_keys(['mssql_to_csv']) retrieved from /usr/local/airflow/dags/__pycache__/mssqlToCSV.py
[2021-09-03 03:21:03,890] {logging_mixin.py:109} INFO - [2021-09-03 03:21:03,890] {dag.py:1833} INFO - Sync 1 DAGs
[2021-09-03 03:21:03,902] {logging_mixin.py:109} INFO - [2021-09-03 03:21:03,902] {dag.py:2306} INFO - Setting next_dagrun for mssql_to_csv to None
[2021-09-03 03:21:03,908] {processor.py:170} INFO - Processing /usr/local/airflow/dags/__pycache__/mssqlToCSV.py took 0.055 seconds
[2021-09-03 03:21:34,024] {processor.py:162} INFO - Started process (PID=252) to work on /usr/local/airflow/dags/__pycache__/mssqlToCSV.py
[2021-09-03 03:21:34,025] {processor.py:613} INFO - Processing file /usr/local/airflow/dags/__pycache__/mssqlToCSV.py for tasks to queue
[2021-09-03 03:21:34,025] {logging_mixin.py:109} INFO - [2021-09-03 03:21:34,025] {dagbag.py:496} INFO - Filling up the DagBag from /usr/local/airflow/dags/__pycache__/mssqlToCSV.py
[2021-09-03 03:21:34,050] {processor.py:623} INFO - DAG(s) dict_keys(['mssql_to_csv']) retrieved from /usr/local/airflow/dags/__pycache__/mssqlToCSV.py
[2021-09-03 03:21:34,069] {logging_mixin.py:109} INFO - [2021-09-03 03:21:34,069] {dag.py:1833} INFO - Sync 1 DAGs
[2021-09-03 03:21:34,083] {logging_mixin.py:109} INFO - [2021-09-03 03:21:34,083] {dag.py:2306} INFO - Setting next_dagrun for mssql_to_csv to None
[2021-09-03 03:21:34,090] {processor.py:170} INFO - Processing /usr/local/airflow/dags/__pycache__/mssqlToCSV.py took 0.069 seconds
[2021-09-03 03:22:04,193] {processor.py:162} INFO - Started process (PID=275) to work on /usr/local/airflow/dags/__pycache__/mssqlToCSV.py
[2021-09-03 03:22:04,193] {processor.py:613} INFO - Processing file /usr/local/airflow/dags/__pycache__/mssqlToCSV.py for tasks to queue
[2021-09-03 03:22:04,194] {logging_mixin.py:109} INFO - [2021-09-03 03:22:04,194] {dagbag.py:496} INFO - Filling up the DagBag from /usr/local/airflow/dags/__pycache__/mssqlToCSV.py
[2021-09-03 03:22:04,214] {processor.py:623} INFO - DAG(s) dict_keys(['mssql_to_csv']) retrieved from /usr/local/airflow/dags/__pycache__/mssqlToCSV.py
[2021-09-03 03:22:04,234] {logging_mixin.py:109} INFO - [2021-09-03 03:22:04,234] {dag.py:1833} INFO - Sync 1 DAGs
[2021-09-03 03:22:04,246] {logging_mixin.py:109} INFO - [2021-09-03 03:22:04,246] {dag.py:2306} INFO - Setting next_dagrun for mssql_to_csv to None
[2021-09-03 03:22:04,252] {processor.py:170} INFO - Processing /usr/local/airflow/dags/__pycache__/mssqlToCSV.py took 0.062 seconds
[2021-09-03 03:22:34,362] {processor.py:162} INFO - Started process (PID=296) to work on /usr/local/airflow/dags/__pycache__/mssqlToCSV.py
[2021-09-03 03:22:34,363] {processor.py:613} INFO - Processing file /usr/local/airflow/dags/__pycache__/mssqlToCSV.py for tasks to queue
[2021-09-03 03:22:34,364] {logging_mixin.py:109} INFO - [2021-09-03 03:22:34,364] {dagbag.py:496} INFO - Filling up the DagBag from /usr/local/airflow/dags/__pycache__/mssqlToCSV.py
[2021-09-03 03:22:34,386] {processor.py:623} INFO - DAG(s) dict_keys(['mssql_to_csv']) retrieved from /usr/local/airflow/dags/__pycache__/mssqlToCSV.py
[2021-09-03 03:22:34,406] {logging_mixin.py:109} INFO - [2021-09-03 03:22:34,406] {dag.py:1833} INFO - Sync 1 DAGs
[2021-09-03 03:22:34,421] {logging_mixin.py:109} INFO - [2021-09-03 03:22:34,421] {dag.py:2306} INFO - Setting next_dagrun for mssql_to_csv to None
[2021-09-03 03:22:34,439] {processor.py:170} INFO - Processing /usr/local/airflow/dags/__pycache__/mssqlToCSV.py took 0.081 seconds
[2021-09-03 03:23:04,527] {processor.py:162} INFO - Started process (PID=317) to work on /usr/local/airflow/dags/__pycache__/mssqlToCSV.py
[2021-09-03 03:23:04,528] {processor.py:613} INFO - Processing file /usr/local/airflow/dags/__pycache__/mssqlToCSV.py for tasks to queue
[2021-09-03 03:23:04,528] {logging_mixin.py:109} INFO - [2021-09-03 03:23:04,528] {dagbag.py:496} INFO - Filling up the DagBag from /usr/local/airflow/dags/__pycache__/mssqlToCSV.py
[2021-09-03 03:23:04,541] {processor.py:623} INFO - DAG(s) dict_keys(['mssql_to_csv']) retrieved from /usr/local/airflow/dags/__pycache__/mssqlToCSV.py
[2021-09-03 03:23:04,554] {logging_mixin.py:109} INFO - [2021-09-03 03:23:04,554] {dag.py:1833} INFO - Sync 1 DAGs
[2021-09-03 03:23:04,564] {logging_mixin.py:109} INFO - [2021-09-03 03:23:04,564] {dag.py:2306} INFO - Setting next_dagrun for mssql_to_csv to None
[2021-09-03 03:23:04,570] {processor.py:170} INFO - Processing /usr/local/airflow/dags/__pycache__/mssqlToCSV.py took 0.045 seconds
[2021-09-03 03:23:34,661] {processor.py:162} INFO - Started process (PID=338) to work on /usr/local/airflow/dags/__pycache__/mssqlToCSV.py
[2021-09-03 03:23:34,662] {processor.py:613} INFO - Processing file /usr/local/airflow/dags/__pycache__/mssqlToCSV.py for tasks to queue
[2021-09-03 03:23:34,663] {logging_mixin.py:109} INFO - [2021-09-03 03:23:34,663] {dagbag.py:496} INFO - Filling up the DagBag from /usr/local/airflow/dags/__pycache__/mssqlToCSV.py
[2021-09-03 03:23:34,679] {processor.py:623} INFO - DAG(s) dict_keys(['mssql_to_csv']) retrieved from /usr/local/airflow/dags/__pycache__/mssqlToCSV.py
[2021-09-03 03:23:34,693] {logging_mixin.py:109} INFO - [2021-09-03 03:23:34,693] {dag.py:1833} INFO - Sync 1 DAGs
[2021-09-03 03:23:34,705] {logging_mixin.py:109} INFO - [2021-09-03 03:23:34,705] {dag.py:2306} INFO - Setting next_dagrun for mssql_to_csv to None
[2021-09-03 03:23:34,711] {processor.py:170} INFO - Processing /usr/local/airflow/dags/__pycache__/mssqlToCSV.py took 0.052 seconds
[2021-09-03 03:24:04,822] {processor.py:162} INFO - Started process (PID=359) to work on /usr/local/airflow/dags/__pycache__/mssqlToCSV.py
[2021-09-03 03:24:04,823] {processor.py:613} INFO - Processing file /usr/local/airflow/dags/__pycache__/mssqlToCSV.py for tasks to queue
[2021-09-03 03:24:04,824] {logging_mixin.py:109} INFO - [2021-09-03 03:24:04,823] {dagbag.py:496} INFO - Filling up the DagBag from /usr/local/airflow/dags/__pycache__/mssqlToCSV.py
[2021-09-03 03:24:04,850] {processor.py:623} INFO - DAG(s) dict_keys(['mssql_to_csv']) retrieved from /usr/local/airflow/dags/__pycache__/mssqlToCSV.py
[2021-09-03 03:24:04,868] {logging_mixin.py:109} INFO - [2021-09-03 03:24:04,868] {dag.py:1833} INFO - Sync 1 DAGs
[2021-09-03 03:24:04,881] {logging_mixin.py:109} INFO - [2021-09-03 03:24:04,880] {dag.py:2306} INFO - Setting next_dagrun for mssql_to_csv to None
[2021-09-03 03:24:04,886] {processor.py:170} INFO - Processing /usr/local/airflow/dags/__pycache__/mssqlToCSV.py took 0.068 seconds
[2021-09-03 03:24:34,996] {processor.py:162} INFO - Started process (PID=380) to work on /usr/local/airflow/dags/__pycache__/mssqlToCSV.py
[2021-09-03 03:24:34,997] {processor.py:613} INFO - Processing file /usr/local/airflow/dags/__pycache__/mssqlToCSV.py for tasks to queue
[2021-09-03 03:24:34,998] {logging_mixin.py:109} INFO - [2021-09-03 03:24:34,998] {dagbag.py:496} INFO - Filling up the DagBag from /usr/local/airflow/dags/__pycache__/mssqlToCSV.py
[2021-09-03 03:24:35,021] {processor.py:623} INFO - DAG(s) dict_keys(['mssql_to_csv']) retrieved from /usr/local/airflow/dags/__pycache__/mssqlToCSV.py
[2021-09-03 03:24:35,042] {logging_mixin.py:109} INFO - [2021-09-03 03:24:35,042] {dag.py:1833} INFO - Sync 1 DAGs
[2021-09-03 03:24:35,057] {logging_mixin.py:109} INFO - [2021-09-03 03:24:35,057] {dag.py:2306} INFO - Setting next_dagrun for mssql_to_csv to None
[2021-09-03 03:24:35,070] {processor.py:170} INFO - Processing /usr/local/airflow/dags/__pycache__/mssqlToCSV.py took 0.078 seconds
[2021-09-03 03:25:05,185] {processor.py:162} INFO - Started process (PID=401) to work on /usr/local/airflow/dags/__pycache__/mssqlToCSV.py
[2021-09-03 03:25:05,187] {processor.py:613} INFO - Processing file /usr/local/airflow/dags/__pycache__/mssqlToCSV.py for tasks to queue
[2021-09-03 03:25:05,187] {logging_mixin.py:109} INFO - [2021-09-03 03:25:05,187] {dagbag.py:496} INFO - Filling up the DagBag from /usr/local/airflow/dags/__pycache__/mssqlToCSV.py
[2021-09-03 03:25:05,210] {processor.py:623} INFO - DAG(s) dict_keys(['mssql_to_csv']) retrieved from /usr/local/airflow/dags/__pycache__/mssqlToCSV.py
[2021-09-03 03:25:05,231] {logging_mixin.py:109} INFO - [2021-09-03 03:25:05,231] {dag.py:1833} INFO - Sync 1 DAGs
[2021-09-03 03:25:05,246] {logging_mixin.py:109} INFO - [2021-09-03 03:25:05,246] {dag.py:2306} INFO - Setting next_dagrun for mssql_to_csv to None
[2021-09-03 03:25:05,256] {processor.py:170} INFO - Processing /usr/local/airflow/dags/__pycache__/mssqlToCSV.py took 0.074 seconds
[2021-09-03 03:25:35,364] {processor.py:162} INFO - Started process (PID=422) to work on /usr/local/airflow/dags/__pycache__/mssqlToCSV.py
[2021-09-03 03:25:35,365] {processor.py:613} INFO - Processing file /usr/local/airflow/dags/__pycache__/mssqlToCSV.py for tasks to queue
[2021-09-03 03:25:35,366] {logging_mixin.py:109} INFO - [2021-09-03 03:25:35,366] {dagbag.py:496} INFO - Filling up the DagBag from /usr/local/airflow/dags/__pycache__/mssqlToCSV.py
[2021-09-03 03:25:35,389] {processor.py:623} INFO - DAG(s) dict_keys(['mssql_to_csv']) retrieved from /usr/local/airflow/dags/__pycache__/mssqlToCSV.py
[2021-09-03 03:25:35,410] {logging_mixin.py:109} INFO - [2021-09-03 03:25:35,410] {dag.py:1833} INFO - Sync 1 DAGs
[2021-09-03 03:25:35,426] {logging_mixin.py:109} INFO - [2021-09-03 03:25:35,426] {dag.py:2306} INFO - Setting next_dagrun for mssql_to_csv to None
[2021-09-03 03:25:35,435] {processor.py:170} INFO - Processing /usr/local/airflow/dags/__pycache__/mssqlToCSV.py took 0.074 seconds
[2021-09-03 03:26:05,564] {processor.py:162} INFO - Started process (PID=443) to work on /usr/local/airflow/dags/__pycache__/mssqlToCSV.py
[2021-09-03 03:26:05,565] {processor.py:613} INFO - Processing file /usr/local/airflow/dags/__pycache__/mssqlToCSV.py for tasks to queue
[2021-09-03 03:26:05,566] {logging_mixin.py:109} INFO - [2021-09-03 03:26:05,566] {dagbag.py:496} INFO - Filling up the DagBag from /usr/local/airflow/dags/__pycache__/mssqlToCSV.py
[2021-09-03 03:26:05,588] {processor.py:623} INFO - DAG(s) dict_keys(['mssql_to_csv']) retrieved from /usr/local/airflow/dags/__pycache__/mssqlToCSV.py
[2021-09-03 03:26:05,608] {logging_mixin.py:109} INFO - [2021-09-03 03:26:05,608] {dag.py:1833} INFO - Sync 1 DAGs
[2021-09-03 03:26:05,623] {logging_mixin.py:109} INFO - [2021-09-03 03:26:05,623] {dag.py:2306} INFO - Setting next_dagrun for mssql_to_csv to None
[2021-09-03 03:26:05,636] {processor.py:170} INFO - Processing /usr/local/airflow/dags/__pycache__/mssqlToCSV.py took 0.075 seconds
[2021-09-03 03:26:35,747] {processor.py:162} INFO - Started process (PID=465) to work on /usr/local/airflow/dags/__pycache__/mssqlToCSV.py
[2021-09-03 03:26:35,749] {processor.py:613} INFO - Processing file /usr/local/airflow/dags/__pycache__/mssqlToCSV.py for tasks to queue
[2021-09-03 03:26:35,750] {logging_mixin.py:109} INFO - [2021-09-03 03:26:35,749] {dagbag.py:496} INFO - Filling up the DagBag from /usr/local/airflow/dags/__pycache__/mssqlToCSV.py
[2021-09-03 03:26:35,772] {processor.py:623} INFO - DAG(s) dict_keys(['mssql_to_csv']) retrieved from /usr/local/airflow/dags/__pycache__/mssqlToCSV.py
[2021-09-03 03:26:35,794] {logging_mixin.py:109} INFO - [2021-09-03 03:26:35,794] {dag.py:1833} INFO - Sync 1 DAGs
[2021-09-03 03:26:35,811] {logging_mixin.py:109} INFO - [2021-09-03 03:26:35,811] {dag.py:2306} INFO - Setting next_dagrun for mssql_to_csv to None
[2021-09-03 03:26:35,829] {processor.py:170} INFO - Processing /usr/local/airflow/dags/__pycache__/mssqlToCSV.py took 0.086 seconds
[2021-09-03 03:27:05,939] {processor.py:162} INFO - Started process (PID=486) to work on /usr/local/airflow/dags/__pycache__/mssqlToCSV.py
[2021-09-03 03:27:05,941] {processor.py:613} INFO - Processing file /usr/local/airflow/dags/__pycache__/mssqlToCSV.py for tasks to queue
[2021-09-03 03:27:05,941] {logging_mixin.py:109} INFO - [2021-09-03 03:27:05,941] {dagbag.py:496} INFO - Filling up the DagBag from /usr/local/airflow/dags/__pycache__/mssqlToCSV.py
[2021-09-03 03:27:05,963] {processor.py:623} INFO - DAG(s) dict_keys(['mssql_to_csv']) retrieved from /usr/local/airflow/dags/__pycache__/mssqlToCSV.py
[2021-09-03 03:27:05,983] {logging_mixin.py:109} INFO - [2021-09-03 03:27:05,983] {dag.py:1833} INFO - Sync 1 DAGs
[2021-09-03 03:27:05,999] {logging_mixin.py:109} INFO - [2021-09-03 03:27:05,999] {dag.py:2306} INFO - Setting next_dagrun for mssql_to_csv to None
[2021-09-03 03:27:06,011] {processor.py:170} INFO - Processing /usr/local/airflow/dags/__pycache__/mssqlToCSV.py took 0.075 seconds
[2021-09-03 03:27:36,103] {processor.py:162} INFO - Started process (PID=507) to work on /usr/local/airflow/dags/__pycache__/mssqlToCSV.py
[2021-09-03 03:27:36,103] {processor.py:613} INFO - Processing file /usr/local/airflow/dags/__pycache__/mssqlToCSV.py for tasks to queue
[2021-09-03 03:27:36,104] {logging_mixin.py:109} INFO - [2021-09-03 03:27:36,104] {dagbag.py:496} INFO - Filling up the DagBag from /usr/local/airflow/dags/__pycache__/mssqlToCSV.py
[2021-09-03 03:27:36,117] {processor.py:623} INFO - DAG(s) dict_keys(['mssql_to_csv']) retrieved from /usr/local/airflow/dags/__pycache__/mssqlToCSV.py
[2021-09-03 03:27:36,134] {logging_mixin.py:109} INFO - [2021-09-03 03:27:36,134] {dag.py:1833} INFO - Sync 1 DAGs
[2021-09-03 03:27:36,145] {logging_mixin.py:109} INFO - [2021-09-03 03:27:36,145] {dag.py:2306} INFO - Setting next_dagrun for mssql_to_csv to None
[2021-09-03 03:27:36,152] {processor.py:170} INFO - Processing /usr/local/airflow/dags/__pycache__/mssqlToCSV.py took 0.051 seconds
[2021-09-03 03:28:06,261] {processor.py:162} INFO - Started process (PID=528) to work on /usr/local/airflow/dags/__pycache__/mssqlToCSV.py
[2021-09-03 03:28:06,262] {processor.py:613} INFO - Processing file /usr/local/airflow/dags/__pycache__/mssqlToCSV.py for tasks to queue
[2021-09-03 03:28:06,262] {logging_mixin.py:109} INFO - [2021-09-03 03:28:06,262] {dagbag.py:496} INFO - Filling up the DagBag from /usr/local/airflow/dags/__pycache__/mssqlToCSV.py
[2021-09-03 03:28:06,275] {processor.py:623} INFO - DAG(s) dict_keys(['mssql_to_csv']) retrieved from /usr/local/airflow/dags/__pycache__/mssqlToCSV.py
[2021-09-03 03:28:06,291] {logging_mixin.py:109} INFO - [2021-09-03 03:28:06,290] {dag.py:1833} INFO - Sync 1 DAGs
[2021-09-03 03:28:06,306] {logging_mixin.py:109} INFO - [2021-09-03 03:28:06,306] {dag.py:2306} INFO - Setting next_dagrun for mssql_to_csv to None
[2021-09-03 03:28:06,314] {processor.py:170} INFO - Processing /usr/local/airflow/dags/__pycache__/mssqlToCSV.py took 0.057 seconds
[2021-09-03 03:28:36,424] {processor.py:162} INFO - Started process (PID=550) to work on /usr/local/airflow/dags/__pycache__/mssqlToCSV.py
[2021-09-03 03:28:36,425] {processor.py:613} INFO - Processing file /usr/local/airflow/dags/__pycache__/mssqlToCSV.py for tasks to queue
[2021-09-03 03:28:36,426] {logging_mixin.py:109} INFO - [2021-09-03 03:28:36,426] {dagbag.py:496} INFO - Filling up the DagBag from /usr/local/airflow/dags/__pycache__/mssqlToCSV.py
[2021-09-03 03:28:36,447] {processor.py:623} INFO - DAG(s) dict_keys(['mssql_to_csv']) retrieved from /usr/local/airflow/dags/__pycache__/mssqlToCSV.py
[2021-09-03 03:28:36,467] {logging_mixin.py:109} INFO - [2021-09-03 03:28:36,467] {dag.py:1833} INFO - Sync 1 DAGs
[2021-09-03 03:28:36,482] {logging_mixin.py:109} INFO - [2021-09-03 03:28:36,482] {dag.py:2306} INFO - Setting next_dagrun for mssql_to_csv to None
[2021-09-03 03:28:36,490] {processor.py:170} INFO - Processing /usr/local/airflow/dags/__pycache__/mssqlToCSV.py took 0.070 seconds
[2021-09-03 03:29:06,611] {processor.py:162} INFO - Started process (PID=571) to work on /usr/local/airflow/dags/__pycache__/mssqlToCSV.py
[2021-09-03 03:29:06,612] {processor.py:613} INFO - Processing file /usr/local/airflow/dags/__pycache__/mssqlToCSV.py for tasks to queue
[2021-09-03 03:29:06,612] {logging_mixin.py:109} INFO - [2021-09-03 03:29:06,612] {dagbag.py:496} INFO - Filling up the DagBag from /usr/local/airflow/dags/__pycache__/mssqlToCSV.py
[2021-09-03 03:29:06,633] {processor.py:623} INFO - DAG(s) dict_keys(['mssql_to_csv']) retrieved from /usr/local/airflow/dags/__pycache__/mssqlToCSV.py
[2021-09-03 03:29:06,653] {logging_mixin.py:109} INFO - [2021-09-03 03:29:06,653] {dag.py:1833} INFO - Sync 1 DAGs
[2021-09-03 03:29:06,668] {logging_mixin.py:109} INFO - [2021-09-03 03:29:06,668] {dag.py:2306} INFO - Setting next_dagrun for mssql_to_csv to None
[2021-09-03 03:29:06,678] {processor.py:170} INFO - Processing /usr/local/airflow/dags/__pycache__/mssqlToCSV.py took 0.070 seconds
[2021-09-03 03:29:36,784] {processor.py:162} INFO - Started process (PID=592) to work on /usr/local/airflow/dags/__pycache__/mssqlToCSV.py
[2021-09-03 03:29:36,785] {processor.py:613} INFO - Processing file /usr/local/airflow/dags/__pycache__/mssqlToCSV.py for tasks to queue
[2021-09-03 03:29:36,786] {logging_mixin.py:109} INFO - [2021-09-03 03:29:36,786] {dagbag.py:496} INFO - Filling up the DagBag from /usr/local/airflow/dags/__pycache__/mssqlToCSV.py
[2021-09-03 03:29:36,803] {processor.py:623} INFO - DAG(s) dict_keys(['mssql_to_csv']) retrieved from /usr/local/airflow/dags/__pycache__/mssqlToCSV.py
[2021-09-03 03:29:36,818] {logging_mixin.py:109} INFO - [2021-09-03 03:29:36,818] {dag.py:1833} INFO - Sync 1 DAGs
[2021-09-03 03:29:36,832] {logging_mixin.py:109} INFO - [2021-09-03 03:29:36,832] {dag.py:2306} INFO - Setting next_dagrun for mssql_to_csv to None
[2021-09-03 03:29:36,839] {processor.py:170} INFO - Processing /usr/local/airflow/dags/__pycache__/mssqlToCSV.py took 0.057 seconds
[2021-09-03 04:00:20,955] {processor.py:162} INFO - Started process (PID=327) to work on /usr/local/airflow/dags/__pycache__/mssqlToCSV.py
[2021-09-03 04:00:20,956] {processor.py:613} INFO - Processing file /usr/local/airflow/dags/__pycache__/mssqlToCSV.py for tasks to queue
[2021-09-03 04:00:20,957] {logging_mixin.py:109} INFO - [2021-09-03 04:00:20,956] {dagbag.py:496} INFO - Filling up the DagBag from /usr/local/airflow/dags/__pycache__/mssqlToCSV.py
[2021-09-03 04:00:20,969] {processor.py:623} INFO - DAG(s) dict_keys(['mssql_to_csv']) retrieved from /usr/local/airflow/dags/__pycache__/mssqlToCSV.py
[2021-09-03 04:00:20,982] {logging_mixin.py:109} INFO - [2021-09-03 04:00:20,982] {dag.py:1833} INFO - Sync 1 DAGs
[2021-09-03 04:00:20,991] {logging_mixin.py:109} INFO - [2021-09-03 04:00:20,991] {dag.py:2306} INFO - Setting next_dagrun for mssql_to_csv to None
[2021-09-03 04:00:20,997] {processor.py:170} INFO - Processing /usr/local/airflow/dags/__pycache__/mssqlToCSV.py took 0.043 seconds
[2021-09-03 04:00:52,444] {processor.py:162} INFO - Started process (PID=551) to work on /usr/local/airflow/dags/__pycache__/mssqlToCSV.py
[2021-09-03 04:00:52,445] {processor.py:613} INFO - Processing file /usr/local/airflow/dags/__pycache__/mssqlToCSV.py for tasks to queue
[2021-09-03 04:00:52,445] {logging_mixin.py:109} INFO - [2021-09-03 04:00:52,445] {dagbag.py:496} INFO - Filling up the DagBag from /usr/local/airflow/dags/__pycache__/mssqlToCSV.py
[2021-09-03 04:00:52,457] {processor.py:623} INFO - DAG(s) dict_keys(['mssql_to_csv']) retrieved from /usr/local/airflow/dags/__pycache__/mssqlToCSV.py
[2021-09-03 04:00:52,469] {logging_mixin.py:109} INFO - [2021-09-03 04:00:52,469] {dag.py:1833} INFO - Sync 1 DAGs
[2021-09-03 04:00:52,477] {logging_mixin.py:109} INFO - [2021-09-03 04:00:52,477] {dag.py:2306} INFO - Setting next_dagrun for mssql_to_csv to None
[2021-09-03 04:00:52,483] {processor.py:170} INFO - Processing /usr/local/airflow/dags/__pycache__/mssqlToCSV.py took 0.041 seconds
[2021-09-03 04:01:24,894] {processor.py:162} INFO - Started process (PID=174) to work on /usr/local/airflow/dags/__pycache__/mssqlToCSV.py
[2021-09-03 04:01:24,895] {processor.py:613} INFO - Processing file /usr/local/airflow/dags/__pycache__/mssqlToCSV.py for tasks to queue
[2021-09-03 04:01:24,895] {logging_mixin.py:109} INFO - [2021-09-03 04:01:24,895] {dagbag.py:496} INFO - Filling up the DagBag from /usr/local/airflow/dags/__pycache__/mssqlToCSV.py
[2021-09-03 04:01:24,913] {processor.py:623} INFO - DAG(s) dict_keys(['mssql_to_csv']) retrieved from /usr/local/airflow/dags/__pycache__/mssqlToCSV.py
[2021-09-03 04:01:24,927] {logging_mixin.py:109} INFO - [2021-09-03 04:01:24,927] {dag.py:1833} INFO - Sync 1 DAGs
[2021-09-03 04:01:24,935] {logging_mixin.py:109} INFO - [2021-09-03 04:01:24,935] {dag.py:2306} INFO - Setting next_dagrun for mssql_to_csv to None
[2021-09-03 04:01:24,942] {processor.py:170} INFO - Processing /usr/local/airflow/dags/__pycache__/mssqlToCSV.py took 0.050 seconds
[2021-09-03 04:01:55,053] {processor.py:162} INFO - Started process (PID=253) to work on /usr/local/airflow/dags/__pycache__/mssqlToCSV.py
[2021-09-03 04:01:55,054] {processor.py:613} INFO - Processing file /usr/local/airflow/dags/__pycache__/mssqlToCSV.py for tasks to queue
[2021-09-03 04:01:55,055] {logging_mixin.py:109} INFO - [2021-09-03 04:01:55,055] {dagbag.py:496} INFO - Filling up the DagBag from /usr/local/airflow/dags/__pycache__/mssqlToCSV.py
[2021-09-03 04:01:55,081] {processor.py:623} INFO - DAG(s) dict_keys(['mssql_to_csv']) retrieved from /usr/local/airflow/dags/__pycache__/mssqlToCSV.py
[2021-09-03 04:01:55,101] {logging_mixin.py:109} INFO - [2021-09-03 04:01:55,101] {dag.py:1833} INFO - Sync 1 DAGs
[2021-09-03 04:01:55,115] {logging_mixin.py:109} INFO - [2021-09-03 04:01:55,114] {dag.py:2306} INFO - Setting next_dagrun for mssql_to_csv to None
[2021-09-03 04:01:55,123] {processor.py:170} INFO - Processing /usr/local/airflow/dags/__pycache__/mssqlToCSV.py took 0.074 seconds
[2021-09-03 04:02:25,240] {processor.py:162} INFO - Started process (PID=274) to work on /usr/local/airflow/dags/__pycache__/mssqlToCSV.py
[2021-09-03 04:02:25,241] {processor.py:613} INFO - Processing file /usr/local/airflow/dags/__pycache__/mssqlToCSV.py for tasks to queue
[2021-09-03 04:02:25,242] {logging_mixin.py:109} INFO - [2021-09-03 04:02:25,242] {dagbag.py:496} INFO - Filling up the DagBag from /usr/local/airflow/dags/__pycache__/mssqlToCSV.py
[2021-09-03 04:02:25,269] {processor.py:623} INFO - DAG(s) dict_keys(['mssql_to_csv']) retrieved from /usr/local/airflow/dags/__pycache__/mssqlToCSV.py
[2021-09-03 04:02:25,292] {logging_mixin.py:109} INFO - [2021-09-03 04:02:25,292] {dag.py:1833} INFO - Sync 1 DAGs
[2021-09-03 04:02:25,306] {logging_mixin.py:109} INFO - [2021-09-03 04:02:25,306] {dag.py:2306} INFO - Setting next_dagrun for mssql_to_csv to None
[2021-09-03 04:02:25,316] {processor.py:170} INFO - Processing /usr/local/airflow/dags/__pycache__/mssqlToCSV.py took 0.080 seconds
[2021-09-03 04:02:55,444] {processor.py:162} INFO - Started process (PID=295) to work on /usr/local/airflow/dags/__pycache__/mssqlToCSV.py
[2021-09-03 04:02:55,445] {processor.py:613} INFO - Processing file /usr/local/airflow/dags/__pycache__/mssqlToCSV.py for tasks to queue
[2021-09-03 04:02:55,446] {logging_mixin.py:109} INFO - [2021-09-03 04:02:55,446] {dagbag.py:496} INFO - Filling up the DagBag from /usr/local/airflow/dags/__pycache__/mssqlToCSV.py
[2021-09-03 04:02:55,468] {processor.py:623} INFO - DAG(s) dict_keys(['mssql_to_csv']) retrieved from /usr/local/airflow/dags/__pycache__/mssqlToCSV.py
[2021-09-03 04:02:56,357] {processor.py:173} ERROR - Got an exception! Propagating...
Traceback (most recent call last):
  File "/usr/local/lib/python3.8/dist-packages/sqlalchemy/engine/base.py", line 2336, in _wrap_pool_connect
    return fn()
  File "/usr/local/lib/python3.8/dist-packages/sqlalchemy/pool/base.py", line 364, in connect
    return _ConnectionFairy._checkout(self)
  File "/usr/local/lib/python3.8/dist-packages/sqlalchemy/pool/base.py", line 778, in _checkout
    fairy = _ConnectionRecord.checkout(pool)
  File "/usr/local/lib/python3.8/dist-packages/sqlalchemy/pool/base.py", line 495, in checkout
    rec = pool._do_get()
  File "/usr/local/lib/python3.8/dist-packages/sqlalchemy/pool/impl.py", line 140, in _do_get
    self._dec_overflow()
  File "/usr/local/lib/python3.8/dist-packages/sqlalchemy/util/langhelpers.py", line 68, in __exit__
    compat.raise_(
  File "/usr/local/lib/python3.8/dist-packages/sqlalchemy/util/compat.py", line 182, in raise_
    raise exception
  File "/usr/local/lib/python3.8/dist-packages/sqlalchemy/pool/impl.py", line 137, in _do_get
    return self._create_connection()
  File "/usr/local/lib/python3.8/dist-packages/sqlalchemy/pool/base.py", line 309, in _create_connection
    return _ConnectionRecord(self)
  File "/usr/local/lib/python3.8/dist-packages/sqlalchemy/pool/base.py", line 440, in __init__
    self.__connect(first_connect_check=True)
  File "/usr/local/lib/python3.8/dist-packages/sqlalchemy/pool/base.py", line 661, in __connect
    pool.logger.debug("Error on connect(): %s", e)
  File "/usr/local/lib/python3.8/dist-packages/sqlalchemy/util/langhelpers.py", line 68, in __exit__
    compat.raise_(
  File "/usr/local/lib/python3.8/dist-packages/sqlalchemy/util/compat.py", line 182, in raise_
    raise exception
  File "/usr/local/lib/python3.8/dist-packages/sqlalchemy/pool/base.py", line 656, in __connect
    connection = pool._invoke_creator(self)
  File "/usr/local/lib/python3.8/dist-packages/sqlalchemy/engine/strategies.py", line 114, in connect
    return dialect.connect(*cargs, **cparams)
  File "/usr/local/lib/python3.8/dist-packages/sqlalchemy/engine/default.py", line 508, in connect
    return self.dbapi.connect(*cargs, **cparams)
  File "/usr/local/lib/python3.8/dist-packages/psycopg2/__init__.py", line 122, in connect
    conn = _connect(dsn, connection_factory=connection_factory, **kwasync)
psycopg2.OperationalError: FATAL:  could not open file "global/pg_filenode.map": Permission denied


The above exception was the direct cause of the following exception:

Traceback (most recent call last):
  File "/usr/local/lib/python3.8/dist-packages/airflow/dag_processing/processor.py", line 164, in _run_file_processor
    result: Tuple[int, int] = dag_file_processor.process_file(
  File "/usr/local/lib/python3.8/dist-packages/airflow/utils/session.py", line 70, in wrapper
    return func(*args, session=session, **kwargs)
  File "/usr/local/lib/python3.8/dist-packages/airflow/dag_processing/processor.py", line 632, in process_file
    dagbag.sync_to_db()
  File "/usr/local/lib/python3.8/dist-packages/airflow/utils/session.py", line 70, in wrapper
    return func(*args, session=session, **kwargs)
  File "/usr/local/lib/python3.8/dist-packages/airflow/models/dagbag.py", line 604, in sync_to_db
    for attempt in run_with_db_retries(logger=self.log):
  File "/usr/local/lib/python3.8/dist-packages/tenacity/__init__.py", line 390, in __iter__
    do = self.iter(retry_state=retry_state)
  File "/usr/local/lib/python3.8/dist-packages/tenacity/__init__.py", line 368, in iter
    raise retry_exc.reraise()
  File "/usr/local/lib/python3.8/dist-packages/tenacity/__init__.py", line 186, in reraise
    raise self.last_attempt.result()
  File "/usr/lib/python3.8/concurrent/futures/_base.py", line 437, in result
    return self.__get_result()
  File "/usr/lib/python3.8/concurrent/futures/_base.py", line 389, in __get_result
    raise self._exception
  File "/usr/local/lib/python3.8/dist-packages/airflow/models/dagbag.py", line 616, in sync_to_db
    serialize_errors.extend(_serialize_dag_capturing_errors(dag, session))
  File "/usr/local/lib/python3.8/dist-packages/airflow/models/dagbag.py", line 587, in _serialize_dag_capturing_errors
    dag_was_updated = SerializedDagModel.write_dag(
  File "/usr/local/lib/python3.8/dist-packages/airflow/utils/session.py", line 67, in wrapper
    return func(*args, **kwargs)
  File "/usr/local/lib/python3.8/dist-packages/airflow/models/serialized_dag.py", line 120, in write_dag
    if session.query(
  File "/usr/local/lib/python3.8/dist-packages/sqlalchemy/orm/query.py", line 3523, in scalar
    ret = self.one()
  File "/usr/local/lib/python3.8/dist-packages/sqlalchemy/orm/query.py", line 3490, in one
    ret = self.one_or_none()
  File "/usr/local/lib/python3.8/dist-packages/sqlalchemy/orm/query.py", line 3459, in one_or_none
    ret = list(self)
  File "/usr/local/lib/python3.8/dist-packages/sqlalchemy/orm/query.py", line 3535, in __iter__
    return self._execute_and_instances(context)
  File "/usr/local/lib/python3.8/dist-packages/sqlalchemy/orm/query.py", line 3556, in _execute_and_instances
    conn = self._get_bind_args(
  File "/usr/local/lib/python3.8/dist-packages/sqlalchemy/orm/query.py", line 3571, in _get_bind_args
    return fn(
  File "/usr/local/lib/python3.8/dist-packages/sqlalchemy/orm/query.py", line 3550, in _connection_from_session
    conn = self.session.connection(**kw)
  File "/usr/local/lib/python3.8/dist-packages/sqlalchemy/orm/session.py", line 1142, in connection
    return self._connection_for_bind(
  File "/usr/local/lib/python3.8/dist-packages/sqlalchemy/orm/session.py", line 1150, in _connection_for_bind
    return self.transaction._connection_for_bind(
  File "/usr/local/lib/python3.8/dist-packages/sqlalchemy/orm/session.py", line 433, in _connection_for_bind
    conn = bind._contextual_connect()
  File "/usr/local/lib/python3.8/dist-packages/sqlalchemy/engine/base.py", line 2302, in _contextual_connect
    self._wrap_pool_connect(self.pool.connect, None),
  File "/usr/local/lib/python3.8/dist-packages/sqlalchemy/engine/base.py", line 2339, in _wrap_pool_connect
    Connection._handle_dbapi_exception_noconnection(
  File "/usr/local/lib/python3.8/dist-packages/sqlalchemy/engine/base.py", line 1583, in _handle_dbapi_exception_noconnection
    util.raise_(
  File "/usr/local/lib/python3.8/dist-packages/sqlalchemy/util/compat.py", line 182, in raise_
    raise exception
  File "/usr/local/lib/python3.8/dist-packages/sqlalchemy/engine/base.py", line 2336, in _wrap_pool_connect
    return fn()
  File "/usr/local/lib/python3.8/dist-packages/sqlalchemy/pool/base.py", line 364, in connect
    return _ConnectionFairy._checkout(self)
  File "/usr/local/lib/python3.8/dist-packages/sqlalchemy/pool/base.py", line 778, in _checkout
    fairy = _ConnectionRecord.checkout(pool)
  File "/usr/local/lib/python3.8/dist-packages/sqlalchemy/pool/base.py", line 495, in checkout
    rec = pool._do_get()
  File "/usr/local/lib/python3.8/dist-packages/sqlalchemy/pool/impl.py", line 140, in _do_get
    self._dec_overflow()
  File "/usr/local/lib/python3.8/dist-packages/sqlalchemy/util/langhelpers.py", line 68, in __exit__
    compat.raise_(
  File "/usr/local/lib/python3.8/dist-packages/sqlalchemy/util/compat.py", line 182, in raise_
    raise exception
  File "/usr/local/lib/python3.8/dist-packages/sqlalchemy/pool/impl.py", line 137, in _do_get
    return self._create_connection()
  File "/usr/local/lib/python3.8/dist-packages/sqlalchemy/pool/base.py", line 309, in _create_connection
    return _ConnectionRecord(self)
  File "/usr/local/lib/python3.8/dist-packages/sqlalchemy/pool/base.py", line 440, in __init__
    self.__connect(first_connect_check=True)
  File "/usr/local/lib/python3.8/dist-packages/sqlalchemy/pool/base.py", line 661, in __connect
    pool.logger.debug("Error on connect(): %s", e)
  File "/usr/local/lib/python3.8/dist-packages/sqlalchemy/util/langhelpers.py", line 68, in __exit__
    compat.raise_(
  File "/usr/local/lib/python3.8/dist-packages/sqlalchemy/util/compat.py", line 182, in raise_
    raise exception
  File "/usr/local/lib/python3.8/dist-packages/sqlalchemy/pool/base.py", line 656, in __connect
    connection = pool._invoke_creator(self)
  File "/usr/local/lib/python3.8/dist-packages/sqlalchemy/engine/strategies.py", line 114, in connect
    return dialect.connect(*cargs, **cparams)
  File "/usr/local/lib/python3.8/dist-packages/sqlalchemy/engine/default.py", line 508, in connect
    return self.dbapi.connect(*cargs, **cparams)
  File "/usr/local/lib/python3.8/dist-packages/psycopg2/__init__.py", line 122, in connect
    conn = _connect(dsn, connection_factory=connection_factory, **kwasync)
sqlalchemy.exc.OperationalError: (psycopg2.OperationalError) FATAL:  could not open file "global/pg_filenode.map": Permission denied

(Background on this error at: http://sqlalche.me/e/13/e3q8)
[2021-09-03 04:03:26,437] {processor.py:162} INFO - Started process (PID=316) to work on /usr/local/airflow/dags/__pycache__/mssqlToCSV.py
[2021-09-03 04:03:26,438] {processor.py:613} INFO - Processing file /usr/local/airflow/dags/__pycache__/mssqlToCSV.py for tasks to queue
[2021-09-03 04:03:26,439] {logging_mixin.py:109} INFO - [2021-09-03 04:03:26,439] {dagbag.py:496} INFO - Filling up the DagBag from /usr/local/airflow/dags/__pycache__/mssqlToCSV.py
[2021-09-03 04:03:26,464] {processor.py:623} INFO - DAG(s) dict_keys(['mssql_to_csv']) retrieved from /usr/local/airflow/dags/__pycache__/mssqlToCSV.py
[2021-09-03 04:03:27,544] {processor.py:173} ERROR - Got an exception! Propagating...
Traceback (most recent call last):
  File "/usr/local/lib/python3.8/dist-packages/sqlalchemy/engine/base.py", line 2336, in _wrap_pool_connect
    return fn()
  File "/usr/local/lib/python3.8/dist-packages/sqlalchemy/pool/base.py", line 364, in connect
    return _ConnectionFairy._checkout(self)
  File "/usr/local/lib/python3.8/dist-packages/sqlalchemy/pool/base.py", line 778, in _checkout
    fairy = _ConnectionRecord.checkout(pool)
  File "/usr/local/lib/python3.8/dist-packages/sqlalchemy/pool/base.py", line 495, in checkout
    rec = pool._do_get()
  File "/usr/local/lib/python3.8/dist-packages/sqlalchemy/pool/impl.py", line 140, in _do_get
    self._dec_overflow()
  File "/usr/local/lib/python3.8/dist-packages/sqlalchemy/util/langhelpers.py", line 68, in __exit__
    compat.raise_(
  File "/usr/local/lib/python3.8/dist-packages/sqlalchemy/util/compat.py", line 182, in raise_
    raise exception
  File "/usr/local/lib/python3.8/dist-packages/sqlalchemy/pool/impl.py", line 137, in _do_get
    return self._create_connection()
  File "/usr/local/lib/python3.8/dist-packages/sqlalchemy/pool/base.py", line 309, in _create_connection
    return _ConnectionRecord(self)
  File "/usr/local/lib/python3.8/dist-packages/sqlalchemy/pool/base.py", line 440, in __init__
    self.__connect(first_connect_check=True)
  File "/usr/local/lib/python3.8/dist-packages/sqlalchemy/pool/base.py", line 661, in __connect
    pool.logger.debug("Error on connect(): %s", e)
  File "/usr/local/lib/python3.8/dist-packages/sqlalchemy/util/langhelpers.py", line 68, in __exit__
    compat.raise_(
  File "/usr/local/lib/python3.8/dist-packages/sqlalchemy/util/compat.py", line 182, in raise_
    raise exception
  File "/usr/local/lib/python3.8/dist-packages/sqlalchemy/pool/base.py", line 656, in __connect
    connection = pool._invoke_creator(self)
  File "/usr/local/lib/python3.8/dist-packages/sqlalchemy/engine/strategies.py", line 114, in connect
    return dialect.connect(*cargs, **cparams)
  File "/usr/local/lib/python3.8/dist-packages/sqlalchemy/engine/default.py", line 508, in connect
    return self.dbapi.connect(*cargs, **cparams)
  File "/usr/local/lib/python3.8/dist-packages/psycopg2/__init__.py", line 122, in connect
    conn = _connect(dsn, connection_factory=connection_factory, **kwasync)
psycopg2.OperationalError: FATAL:  could not open file "global/pg_filenode.map": Permission denied


The above exception was the direct cause of the following exception:

Traceback (most recent call last):
  File "/usr/local/lib/python3.8/dist-packages/airflow/dag_processing/processor.py", line 164, in _run_file_processor
    result: Tuple[int, int] = dag_file_processor.process_file(
  File "/usr/local/lib/python3.8/dist-packages/airflow/utils/session.py", line 70, in wrapper
    return func(*args, session=session, **kwargs)
  File "/usr/local/lib/python3.8/dist-packages/airflow/dag_processing/processor.py", line 632, in process_file
    dagbag.sync_to_db()
  File "/usr/local/lib/python3.8/dist-packages/airflow/utils/session.py", line 70, in wrapper
    return func(*args, session=session, **kwargs)
  File "/usr/local/lib/python3.8/dist-packages/airflow/models/dagbag.py", line 604, in sync_to_db
    for attempt in run_with_db_retries(logger=self.log):
  File "/usr/local/lib/python3.8/dist-packages/tenacity/__init__.py", line 390, in __iter__
    do = self.iter(retry_state=retry_state)
  File "/usr/local/lib/python3.8/dist-packages/tenacity/__init__.py", line 368, in iter
    raise retry_exc.reraise()
  File "/usr/local/lib/python3.8/dist-packages/tenacity/__init__.py", line 186, in reraise
    raise self.last_attempt.result()
  File "/usr/lib/python3.8/concurrent/futures/_base.py", line 437, in result
    return self.__get_result()
  File "/usr/lib/python3.8/concurrent/futures/_base.py", line 389, in __get_result
    raise self._exception
  File "/usr/local/lib/python3.8/dist-packages/airflow/models/dagbag.py", line 616, in sync_to_db
    serialize_errors.extend(_serialize_dag_capturing_errors(dag, session))
  File "/usr/local/lib/python3.8/dist-packages/airflow/models/dagbag.py", line 587, in _serialize_dag_capturing_errors
    dag_was_updated = SerializedDagModel.write_dag(
  File "/usr/local/lib/python3.8/dist-packages/airflow/utils/session.py", line 67, in wrapper
    return func(*args, **kwargs)
  File "/usr/local/lib/python3.8/dist-packages/airflow/models/serialized_dag.py", line 120, in write_dag
    if session.query(
  File "/usr/local/lib/python3.8/dist-packages/sqlalchemy/orm/query.py", line 3523, in scalar
    ret = self.one()
  File "/usr/local/lib/python3.8/dist-packages/sqlalchemy/orm/query.py", line 3490, in one
    ret = self.one_or_none()
  File "/usr/local/lib/python3.8/dist-packages/sqlalchemy/orm/query.py", line 3459, in one_or_none
    ret = list(self)
  File "/usr/local/lib/python3.8/dist-packages/sqlalchemy/orm/query.py", line 3535, in __iter__
    return self._execute_and_instances(context)
  File "/usr/local/lib/python3.8/dist-packages/sqlalchemy/orm/query.py", line 3556, in _execute_and_instances
    conn = self._get_bind_args(
  File "/usr/local/lib/python3.8/dist-packages/sqlalchemy/orm/query.py", line 3571, in _get_bind_args
    return fn(
  File "/usr/local/lib/python3.8/dist-packages/sqlalchemy/orm/query.py", line 3550, in _connection_from_session
    conn = self.session.connection(**kw)
  File "/usr/local/lib/python3.8/dist-packages/sqlalchemy/orm/session.py", line 1142, in connection
    return self._connection_for_bind(
  File "/usr/local/lib/python3.8/dist-packages/sqlalchemy/orm/session.py", line 1150, in _connection_for_bind
    return self.transaction._connection_for_bind(
  File "/usr/local/lib/python3.8/dist-packages/sqlalchemy/orm/session.py", line 433, in _connection_for_bind
    conn = bind._contextual_connect()
  File "/usr/local/lib/python3.8/dist-packages/sqlalchemy/engine/base.py", line 2302, in _contextual_connect
    self._wrap_pool_connect(self.pool.connect, None),
  File "/usr/local/lib/python3.8/dist-packages/sqlalchemy/engine/base.py", line 2339, in _wrap_pool_connect
    Connection._handle_dbapi_exception_noconnection(
  File "/usr/local/lib/python3.8/dist-packages/sqlalchemy/engine/base.py", line 1583, in _handle_dbapi_exception_noconnection
    util.raise_(
  File "/usr/local/lib/python3.8/dist-packages/sqlalchemy/util/compat.py", line 182, in raise_
    raise exception
  File "/usr/local/lib/python3.8/dist-packages/sqlalchemy/engine/base.py", line 2336, in _wrap_pool_connect
    return fn()
  File "/usr/local/lib/python3.8/dist-packages/sqlalchemy/pool/base.py", line 364, in connect
    return _ConnectionFairy._checkout(self)
  File "/usr/local/lib/python3.8/dist-packages/sqlalchemy/pool/base.py", line 778, in _checkout
    fairy = _ConnectionRecord.checkout(pool)
  File "/usr/local/lib/python3.8/dist-packages/sqlalchemy/pool/base.py", line 495, in checkout
    rec = pool._do_get()
  File "/usr/local/lib/python3.8/dist-packages/sqlalchemy/pool/impl.py", line 140, in _do_get
    self._dec_overflow()
  File "/usr/local/lib/python3.8/dist-packages/sqlalchemy/util/langhelpers.py", line 68, in __exit__
    compat.raise_(
  File "/usr/local/lib/python3.8/dist-packages/sqlalchemy/util/compat.py", line 182, in raise_
    raise exception
  File "/usr/local/lib/python3.8/dist-packages/sqlalchemy/pool/impl.py", line 137, in _do_get
    return self._create_connection()
  File "/usr/local/lib/python3.8/dist-packages/sqlalchemy/pool/base.py", line 309, in _create_connection
    return _ConnectionRecord(self)
  File "/usr/local/lib/python3.8/dist-packages/sqlalchemy/pool/base.py", line 440, in __init__
    self.__connect(first_connect_check=True)
  File "/usr/local/lib/python3.8/dist-packages/sqlalchemy/pool/base.py", line 661, in __connect
    pool.logger.debug("Error on connect(): %s", e)
  File "/usr/local/lib/python3.8/dist-packages/sqlalchemy/util/langhelpers.py", line 68, in __exit__
    compat.raise_(
  File "/usr/local/lib/python3.8/dist-packages/sqlalchemy/util/compat.py", line 182, in raise_
    raise exception
  File "/usr/local/lib/python3.8/dist-packages/sqlalchemy/pool/base.py", line 656, in __connect
    connection = pool._invoke_creator(self)
  File "/usr/local/lib/python3.8/dist-packages/sqlalchemy/engine/strategies.py", line 114, in connect
    return dialect.connect(*cargs, **cparams)
  File "/usr/local/lib/python3.8/dist-packages/sqlalchemy/engine/default.py", line 508, in connect
    return self.dbapi.connect(*cargs, **cparams)
  File "/usr/local/lib/python3.8/dist-packages/psycopg2/__init__.py", line 122, in connect
    conn = _connect(dsn, connection_factory=connection_factory, **kwasync)
sqlalchemy.exc.OperationalError: (psycopg2.OperationalError) FATAL:  could not open file "global/pg_filenode.map": Permission denied

(Background on this error at: http://sqlalche.me/e/13/e3q8)
[2021-09-03 04:03:57,937] {processor.py:162} INFO - Started process (PID=338) to work on /usr/local/airflow/dags/__pycache__/mssqlToCSV.py
[2021-09-03 04:03:57,938] {processor.py:613} INFO - Processing file /usr/local/airflow/dags/__pycache__/mssqlToCSV.py for tasks to queue
[2021-09-03 04:03:57,939] {logging_mixin.py:109} INFO - [2021-09-03 04:03:57,939] {dagbag.py:496} INFO - Filling up the DagBag from /usr/local/airflow/dags/__pycache__/mssqlToCSV.py
[2021-09-03 04:03:57,960] {processor.py:623} INFO - DAG(s) dict_keys(['mssql_to_csv']) retrieved from /usr/local/airflow/dags/__pycache__/mssqlToCSV.py
[2021-09-03 04:03:58,830] {processor.py:173} ERROR - Got an exception! Propagating...
Traceback (most recent call last):
  File "/usr/local/lib/python3.8/dist-packages/sqlalchemy/engine/base.py", line 2336, in _wrap_pool_connect
    return fn()
  File "/usr/local/lib/python3.8/dist-packages/sqlalchemy/pool/base.py", line 364, in connect
    return _ConnectionFairy._checkout(self)
  File "/usr/local/lib/python3.8/dist-packages/sqlalchemy/pool/base.py", line 778, in _checkout
    fairy = _ConnectionRecord.checkout(pool)
  File "/usr/local/lib/python3.8/dist-packages/sqlalchemy/pool/base.py", line 495, in checkout
    rec = pool._do_get()
  File "/usr/local/lib/python3.8/dist-packages/sqlalchemy/pool/impl.py", line 140, in _do_get
    self._dec_overflow()
  File "/usr/local/lib/python3.8/dist-packages/sqlalchemy/util/langhelpers.py", line 68, in __exit__
    compat.raise_(
  File "/usr/local/lib/python3.8/dist-packages/sqlalchemy/util/compat.py", line 182, in raise_
    raise exception
  File "/usr/local/lib/python3.8/dist-packages/sqlalchemy/pool/impl.py", line 137, in _do_get
    return self._create_connection()
  File "/usr/local/lib/python3.8/dist-packages/sqlalchemy/pool/base.py", line 309, in _create_connection
    return _ConnectionRecord(self)
  File "/usr/local/lib/python3.8/dist-packages/sqlalchemy/pool/base.py", line 440, in __init__
    self.__connect(first_connect_check=True)
  File "/usr/local/lib/python3.8/dist-packages/sqlalchemy/pool/base.py", line 661, in __connect
    pool.logger.debug("Error on connect(): %s", e)
  File "/usr/local/lib/python3.8/dist-packages/sqlalchemy/util/langhelpers.py", line 68, in __exit__
    compat.raise_(
  File "/usr/local/lib/python3.8/dist-packages/sqlalchemy/util/compat.py", line 182, in raise_
    raise exception
  File "/usr/local/lib/python3.8/dist-packages/sqlalchemy/pool/base.py", line 656, in __connect
    connection = pool._invoke_creator(self)
  File "/usr/local/lib/python3.8/dist-packages/sqlalchemy/engine/strategies.py", line 114, in connect
    return dialect.connect(*cargs, **cparams)
  File "/usr/local/lib/python3.8/dist-packages/sqlalchemy/engine/default.py", line 508, in connect
    return self.dbapi.connect(*cargs, **cparams)
  File "/usr/local/lib/python3.8/dist-packages/psycopg2/__init__.py", line 122, in connect
    conn = _connect(dsn, connection_factory=connection_factory, **kwasync)
psycopg2.OperationalError: FATAL:  could not open file "global/pg_filenode.map": Permission denied


The above exception was the direct cause of the following exception:

Traceback (most recent call last):
  File "/usr/local/lib/python3.8/dist-packages/airflow/dag_processing/processor.py", line 164, in _run_file_processor
    result: Tuple[int, int] = dag_file_processor.process_file(
  File "/usr/local/lib/python3.8/dist-packages/airflow/utils/session.py", line 70, in wrapper
    return func(*args, session=session, **kwargs)
  File "/usr/local/lib/python3.8/dist-packages/airflow/dag_processing/processor.py", line 632, in process_file
    dagbag.sync_to_db()
  File "/usr/local/lib/python3.8/dist-packages/airflow/utils/session.py", line 70, in wrapper
    return func(*args, session=session, **kwargs)
  File "/usr/local/lib/python3.8/dist-packages/airflow/models/dagbag.py", line 604, in sync_to_db
    for attempt in run_with_db_retries(logger=self.log):
  File "/usr/local/lib/python3.8/dist-packages/tenacity/__init__.py", line 390, in __iter__
    do = self.iter(retry_state=retry_state)
  File "/usr/local/lib/python3.8/dist-packages/tenacity/__init__.py", line 368, in iter
    raise retry_exc.reraise()
  File "/usr/local/lib/python3.8/dist-packages/tenacity/__init__.py", line 186, in reraise
    raise self.last_attempt.result()
  File "/usr/lib/python3.8/concurrent/futures/_base.py", line 437, in result
    return self.__get_result()
  File "/usr/lib/python3.8/concurrent/futures/_base.py", line 389, in __get_result
    raise self._exception
  File "/usr/local/lib/python3.8/dist-packages/airflow/models/dagbag.py", line 616, in sync_to_db
    serialize_errors.extend(_serialize_dag_capturing_errors(dag, session))
  File "/usr/local/lib/python3.8/dist-packages/airflow/models/dagbag.py", line 587, in _serialize_dag_capturing_errors
    dag_was_updated = SerializedDagModel.write_dag(
  File "/usr/local/lib/python3.8/dist-packages/airflow/utils/session.py", line 67, in wrapper
    return func(*args, **kwargs)
  File "/usr/local/lib/python3.8/dist-packages/airflow/models/serialized_dag.py", line 120, in write_dag
    if session.query(
  File "/usr/local/lib/python3.8/dist-packages/sqlalchemy/orm/query.py", line 3523, in scalar
    ret = self.one()
  File "/usr/local/lib/python3.8/dist-packages/sqlalchemy/orm/query.py", line 3490, in one
    ret = self.one_or_none()
  File "/usr/local/lib/python3.8/dist-packages/sqlalchemy/orm/query.py", line 3459, in one_or_none
    ret = list(self)
  File "/usr/local/lib/python3.8/dist-packages/sqlalchemy/orm/query.py", line 3535, in __iter__
    return self._execute_and_instances(context)
  File "/usr/local/lib/python3.8/dist-packages/sqlalchemy/orm/query.py", line 3556, in _execute_and_instances
    conn = self._get_bind_args(
  File "/usr/local/lib/python3.8/dist-packages/sqlalchemy/orm/query.py", line 3571, in _get_bind_args
    return fn(
  File "/usr/local/lib/python3.8/dist-packages/sqlalchemy/orm/query.py", line 3550, in _connection_from_session
    conn = self.session.connection(**kw)
  File "/usr/local/lib/python3.8/dist-packages/sqlalchemy/orm/session.py", line 1142, in connection
    return self._connection_for_bind(
  File "/usr/local/lib/python3.8/dist-packages/sqlalchemy/orm/session.py", line 1150, in _connection_for_bind
    return self.transaction._connection_for_bind(
  File "/usr/local/lib/python3.8/dist-packages/sqlalchemy/orm/session.py", line 433, in _connection_for_bind
    conn = bind._contextual_connect()
  File "/usr/local/lib/python3.8/dist-packages/sqlalchemy/engine/base.py", line 2302, in _contextual_connect
    self._wrap_pool_connect(self.pool.connect, None),
  File "/usr/local/lib/python3.8/dist-packages/sqlalchemy/engine/base.py", line 2339, in _wrap_pool_connect
    Connection._handle_dbapi_exception_noconnection(
  File "/usr/local/lib/python3.8/dist-packages/sqlalchemy/engine/base.py", line 1583, in _handle_dbapi_exception_noconnection
    util.raise_(
  File "/usr/local/lib/python3.8/dist-packages/sqlalchemy/util/compat.py", line 182, in raise_
    raise exception
  File "/usr/local/lib/python3.8/dist-packages/sqlalchemy/engine/base.py", line 2336, in _wrap_pool_connect
    return fn()
  File "/usr/local/lib/python3.8/dist-packages/sqlalchemy/pool/base.py", line 364, in connect
    return _ConnectionFairy._checkout(self)
  File "/usr/local/lib/python3.8/dist-packages/sqlalchemy/pool/base.py", line 778, in _checkout
    fairy = _ConnectionRecord.checkout(pool)
  File "/usr/local/lib/python3.8/dist-packages/sqlalchemy/pool/base.py", line 495, in checkout
    rec = pool._do_get()
  File "/usr/local/lib/python3.8/dist-packages/sqlalchemy/pool/impl.py", line 140, in _do_get
    self._dec_overflow()
  File "/usr/local/lib/python3.8/dist-packages/sqlalchemy/util/langhelpers.py", line 68, in __exit__
    compat.raise_(
  File "/usr/local/lib/python3.8/dist-packages/sqlalchemy/util/compat.py", line 182, in raise_
    raise exception
  File "/usr/local/lib/python3.8/dist-packages/sqlalchemy/pool/impl.py", line 137, in _do_get
    return self._create_connection()
  File "/usr/local/lib/python3.8/dist-packages/sqlalchemy/pool/base.py", line 309, in _create_connection
    return _ConnectionRecord(self)
  File "/usr/local/lib/python3.8/dist-packages/sqlalchemy/pool/base.py", line 440, in __init__
    self.__connect(first_connect_check=True)
  File "/usr/local/lib/python3.8/dist-packages/sqlalchemy/pool/base.py", line 661, in __connect
    pool.logger.debug("Error on connect(): %s", e)
  File "/usr/local/lib/python3.8/dist-packages/sqlalchemy/util/langhelpers.py", line 68, in __exit__
    compat.raise_(
  File "/usr/local/lib/python3.8/dist-packages/sqlalchemy/util/compat.py", line 182, in raise_
    raise exception
  File "/usr/local/lib/python3.8/dist-packages/sqlalchemy/pool/base.py", line 656, in __connect
    connection = pool._invoke_creator(self)
  File "/usr/local/lib/python3.8/dist-packages/sqlalchemy/engine/strategies.py", line 114, in connect
    return dialect.connect(*cargs, **cparams)
  File "/usr/local/lib/python3.8/dist-packages/sqlalchemy/engine/default.py", line 508, in connect
    return self.dbapi.connect(*cargs, **cparams)
  File "/usr/local/lib/python3.8/dist-packages/psycopg2/__init__.py", line 122, in connect
    conn = _connect(dsn, connection_factory=connection_factory, **kwasync)
sqlalchemy.exc.OperationalError: (psycopg2.OperationalError) FATAL:  could not open file "global/pg_filenode.map": Permission denied

(Background on this error at: http://sqlalche.me/e/13/e3q8)
[2021-09-03 04:04:28,948] {processor.py:162} INFO - Started process (PID=360) to work on /usr/local/airflow/dags/__pycache__/mssqlToCSV.py
[2021-09-03 04:04:28,949] {processor.py:613} INFO - Processing file /usr/local/airflow/dags/__pycache__/mssqlToCSV.py for tasks to queue
[2021-09-03 04:04:28,950] {logging_mixin.py:109} INFO - [2021-09-03 04:04:28,950] {dagbag.py:496} INFO - Filling up the DagBag from /usr/local/airflow/dags/__pycache__/mssqlToCSV.py
[2021-09-03 04:04:28,971] {processor.py:623} INFO - DAG(s) dict_keys(['mssql_to_csv']) retrieved from /usr/local/airflow/dags/__pycache__/mssqlToCSV.py
[2021-09-03 04:04:29,623] {processor.py:173} ERROR - Got an exception! Propagating...
Traceback (most recent call last):
  File "/usr/local/lib/python3.8/dist-packages/sqlalchemy/engine/base.py", line 2336, in _wrap_pool_connect
    return fn()
  File "/usr/local/lib/python3.8/dist-packages/sqlalchemy/pool/base.py", line 364, in connect
    return _ConnectionFairy._checkout(self)
  File "/usr/local/lib/python3.8/dist-packages/sqlalchemy/pool/base.py", line 778, in _checkout
    fairy = _ConnectionRecord.checkout(pool)
  File "/usr/local/lib/python3.8/dist-packages/sqlalchemy/pool/base.py", line 495, in checkout
    rec = pool._do_get()
  File "/usr/local/lib/python3.8/dist-packages/sqlalchemy/pool/impl.py", line 140, in _do_get
    self._dec_overflow()
  File "/usr/local/lib/python3.8/dist-packages/sqlalchemy/util/langhelpers.py", line 68, in __exit__
    compat.raise_(
  File "/usr/local/lib/python3.8/dist-packages/sqlalchemy/util/compat.py", line 182, in raise_
    raise exception
  File "/usr/local/lib/python3.8/dist-packages/sqlalchemy/pool/impl.py", line 137, in _do_get
    return self._create_connection()
  File "/usr/local/lib/python3.8/dist-packages/sqlalchemy/pool/base.py", line 309, in _create_connection
    return _ConnectionRecord(self)
  File "/usr/local/lib/python3.8/dist-packages/sqlalchemy/pool/base.py", line 440, in __init__
    self.__connect(first_connect_check=True)
  File "/usr/local/lib/python3.8/dist-packages/sqlalchemy/pool/base.py", line 661, in __connect
    pool.logger.debug("Error on connect(): %s", e)
  File "/usr/local/lib/python3.8/dist-packages/sqlalchemy/util/langhelpers.py", line 68, in __exit__
    compat.raise_(
  File "/usr/local/lib/python3.8/dist-packages/sqlalchemy/util/compat.py", line 182, in raise_
    raise exception
  File "/usr/local/lib/python3.8/dist-packages/sqlalchemy/pool/base.py", line 656, in __connect
    connection = pool._invoke_creator(self)
  File "/usr/local/lib/python3.8/dist-packages/sqlalchemy/engine/strategies.py", line 114, in connect
    return dialect.connect(*cargs, **cparams)
  File "/usr/local/lib/python3.8/dist-packages/sqlalchemy/engine/default.py", line 508, in connect
    return self.dbapi.connect(*cargs, **cparams)
  File "/usr/local/lib/python3.8/dist-packages/psycopg2/__init__.py", line 122, in connect
    conn = _connect(dsn, connection_factory=connection_factory, **kwasync)
psycopg2.OperationalError: FATAL:  could not open file "global/pg_filenode.map": Permission denied


The above exception was the direct cause of the following exception:

Traceback (most recent call last):
  File "/usr/local/lib/python3.8/dist-packages/airflow/dag_processing/processor.py", line 164, in _run_file_processor
    result: Tuple[int, int] = dag_file_processor.process_file(
  File "/usr/local/lib/python3.8/dist-packages/airflow/utils/session.py", line 70, in wrapper
    return func(*args, session=session, **kwargs)
  File "/usr/local/lib/python3.8/dist-packages/airflow/dag_processing/processor.py", line 632, in process_file
    dagbag.sync_to_db()
  File "/usr/local/lib/python3.8/dist-packages/airflow/utils/session.py", line 70, in wrapper
    return func(*args, session=session, **kwargs)
  File "/usr/local/lib/python3.8/dist-packages/airflow/models/dagbag.py", line 604, in sync_to_db
    for attempt in run_with_db_retries(logger=self.log):
  File "/usr/local/lib/python3.8/dist-packages/tenacity/__init__.py", line 390, in __iter__
    do = self.iter(retry_state=retry_state)
  File "/usr/local/lib/python3.8/dist-packages/tenacity/__init__.py", line 368, in iter
    raise retry_exc.reraise()
  File "/usr/local/lib/python3.8/dist-packages/tenacity/__init__.py", line 186, in reraise
    raise self.last_attempt.result()
  File "/usr/lib/python3.8/concurrent/futures/_base.py", line 437, in result
    return self.__get_result()
  File "/usr/lib/python3.8/concurrent/futures/_base.py", line 389, in __get_result
    raise self._exception
  File "/usr/local/lib/python3.8/dist-packages/airflow/models/dagbag.py", line 616, in sync_to_db
    serialize_errors.extend(_serialize_dag_capturing_errors(dag, session))
  File "/usr/local/lib/python3.8/dist-packages/airflow/models/dagbag.py", line 587, in _serialize_dag_capturing_errors
    dag_was_updated = SerializedDagModel.write_dag(
  File "/usr/local/lib/python3.8/dist-packages/airflow/utils/session.py", line 67, in wrapper
    return func(*args, **kwargs)
  File "/usr/local/lib/python3.8/dist-packages/airflow/models/serialized_dag.py", line 120, in write_dag
    if session.query(
  File "/usr/local/lib/python3.8/dist-packages/sqlalchemy/orm/query.py", line 3523, in scalar
    ret = self.one()
  File "/usr/local/lib/python3.8/dist-packages/sqlalchemy/orm/query.py", line 3490, in one
    ret = self.one_or_none()
  File "/usr/local/lib/python3.8/dist-packages/sqlalchemy/orm/query.py", line 3459, in one_or_none
    ret = list(self)
  File "/usr/local/lib/python3.8/dist-packages/sqlalchemy/orm/query.py", line 3535, in __iter__
    return self._execute_and_instances(context)
  File "/usr/local/lib/python3.8/dist-packages/sqlalchemy/orm/query.py", line 3556, in _execute_and_instances
    conn = self._get_bind_args(
  File "/usr/local/lib/python3.8/dist-packages/sqlalchemy/orm/query.py", line 3571, in _get_bind_args
    return fn(
  File "/usr/local/lib/python3.8/dist-packages/sqlalchemy/orm/query.py", line 3550, in _connection_from_session
    conn = self.session.connection(**kw)
  File "/usr/local/lib/python3.8/dist-packages/sqlalchemy/orm/session.py", line 1142, in connection
    return self._connection_for_bind(
  File "/usr/local/lib/python3.8/dist-packages/sqlalchemy/orm/session.py", line 1150, in _connection_for_bind
    return self.transaction._connection_for_bind(
  File "/usr/local/lib/python3.8/dist-packages/sqlalchemy/orm/session.py", line 433, in _connection_for_bind
    conn = bind._contextual_connect()
  File "/usr/local/lib/python3.8/dist-packages/sqlalchemy/engine/base.py", line 2302, in _contextual_connect
    self._wrap_pool_connect(self.pool.connect, None),
  File "/usr/local/lib/python3.8/dist-packages/sqlalchemy/engine/base.py", line 2339, in _wrap_pool_connect
    Connection._handle_dbapi_exception_noconnection(
  File "/usr/local/lib/python3.8/dist-packages/sqlalchemy/engine/base.py", line 1583, in _handle_dbapi_exception_noconnection
    util.raise_(
  File "/usr/local/lib/python3.8/dist-packages/sqlalchemy/util/compat.py", line 182, in raise_
    raise exception
  File "/usr/local/lib/python3.8/dist-packages/sqlalchemy/engine/base.py", line 2336, in _wrap_pool_connect
    return fn()
  File "/usr/local/lib/python3.8/dist-packages/sqlalchemy/pool/base.py", line 364, in connect
    return _ConnectionFairy._checkout(self)
  File "/usr/local/lib/python3.8/dist-packages/sqlalchemy/pool/base.py", line 778, in _checkout
    fairy = _ConnectionRecord.checkout(pool)
  File "/usr/local/lib/python3.8/dist-packages/sqlalchemy/pool/base.py", line 495, in checkout
    rec = pool._do_get()
  File "/usr/local/lib/python3.8/dist-packages/sqlalchemy/pool/impl.py", line 140, in _do_get
    self._dec_overflow()
  File "/usr/local/lib/python3.8/dist-packages/sqlalchemy/util/langhelpers.py", line 68, in __exit__
    compat.raise_(
  File "/usr/local/lib/python3.8/dist-packages/sqlalchemy/util/compat.py", line 182, in raise_
    raise exception
  File "/usr/local/lib/python3.8/dist-packages/sqlalchemy/pool/impl.py", line 137, in _do_get
    return self._create_connection()
  File "/usr/local/lib/python3.8/dist-packages/sqlalchemy/pool/base.py", line 309, in _create_connection
    return _ConnectionRecord(self)
  File "/usr/local/lib/python3.8/dist-packages/sqlalchemy/pool/base.py", line 440, in __init__
    self.__connect(first_connect_check=True)
  File "/usr/local/lib/python3.8/dist-packages/sqlalchemy/pool/base.py", line 661, in __connect
    pool.logger.debug("Error on connect(): %s", e)
  File "/usr/local/lib/python3.8/dist-packages/sqlalchemy/util/langhelpers.py", line 68, in __exit__
    compat.raise_(
  File "/usr/local/lib/python3.8/dist-packages/sqlalchemy/util/compat.py", line 182, in raise_
    raise exception
  File "/usr/local/lib/python3.8/dist-packages/sqlalchemy/pool/base.py", line 656, in __connect
    connection = pool._invoke_creator(self)
  File "/usr/local/lib/python3.8/dist-packages/sqlalchemy/engine/strategies.py", line 114, in connect
    return dialect.connect(*cargs, **cparams)
  File "/usr/local/lib/python3.8/dist-packages/sqlalchemy/engine/default.py", line 508, in connect
    return self.dbapi.connect(*cargs, **cparams)
  File "/usr/local/lib/python3.8/dist-packages/psycopg2/__init__.py", line 122, in connect
    conn = _connect(dsn, connection_factory=connection_factory, **kwasync)
sqlalchemy.exc.OperationalError: (psycopg2.OperationalError) FATAL:  could not open file "global/pg_filenode.map": Permission denied

(Background on this error at: http://sqlalche.me/e/13/e3q8)
[2021-09-03 04:04:59,705] {processor.py:162} INFO - Started process (PID=381) to work on /usr/local/airflow/dags/__pycache__/mssqlToCSV.py
[2021-09-03 04:04:59,706] {processor.py:613} INFO - Processing file /usr/local/airflow/dags/__pycache__/mssqlToCSV.py for tasks to queue
[2021-09-03 04:04:59,706] {logging_mixin.py:109} INFO - [2021-09-03 04:04:59,706] {dagbag.py:496} INFO - Filling up the DagBag from /usr/local/airflow/dags/__pycache__/mssqlToCSV.py
[2021-09-03 04:04:59,730] {processor.py:623} INFO - DAG(s) dict_keys(['mssql_to_csv']) retrieved from /usr/local/airflow/dags/__pycache__/mssqlToCSV.py
[2021-09-03 04:05:00,251] {processor.py:173} ERROR - Got an exception! Propagating...
Traceback (most recent call last):
  File "/usr/local/lib/python3.8/dist-packages/sqlalchemy/engine/base.py", line 2336, in _wrap_pool_connect
    return fn()
  File "/usr/local/lib/python3.8/dist-packages/sqlalchemy/pool/base.py", line 364, in connect
    return _ConnectionFairy._checkout(self)
  File "/usr/local/lib/python3.8/dist-packages/sqlalchemy/pool/base.py", line 778, in _checkout
    fairy = _ConnectionRecord.checkout(pool)
  File "/usr/local/lib/python3.8/dist-packages/sqlalchemy/pool/base.py", line 495, in checkout
    rec = pool._do_get()
  File "/usr/local/lib/python3.8/dist-packages/sqlalchemy/pool/impl.py", line 140, in _do_get
    self._dec_overflow()
  File "/usr/local/lib/python3.8/dist-packages/sqlalchemy/util/langhelpers.py", line 68, in __exit__
    compat.raise_(
  File "/usr/local/lib/python3.8/dist-packages/sqlalchemy/util/compat.py", line 182, in raise_
    raise exception
  File "/usr/local/lib/python3.8/dist-packages/sqlalchemy/pool/impl.py", line 137, in _do_get
    return self._create_connection()
  File "/usr/local/lib/python3.8/dist-packages/sqlalchemy/pool/base.py", line 309, in _create_connection
    return _ConnectionRecord(self)
  File "/usr/local/lib/python3.8/dist-packages/sqlalchemy/pool/base.py", line 440, in __init__
    self.__connect(first_connect_check=True)
  File "/usr/local/lib/python3.8/dist-packages/sqlalchemy/pool/base.py", line 661, in __connect
    pool.logger.debug("Error on connect(): %s", e)
  File "/usr/local/lib/python3.8/dist-packages/sqlalchemy/util/langhelpers.py", line 68, in __exit__
    compat.raise_(
  File "/usr/local/lib/python3.8/dist-packages/sqlalchemy/util/compat.py", line 182, in raise_
    raise exception
  File "/usr/local/lib/python3.8/dist-packages/sqlalchemy/pool/base.py", line 656, in __connect
    connection = pool._invoke_creator(self)
  File "/usr/local/lib/python3.8/dist-packages/sqlalchemy/engine/strategies.py", line 114, in connect
    return dialect.connect(*cargs, **cparams)
  File "/usr/local/lib/python3.8/dist-packages/sqlalchemy/engine/default.py", line 508, in connect
    return self.dbapi.connect(*cargs, **cparams)
  File "/usr/local/lib/python3.8/dist-packages/psycopg2/__init__.py", line 122, in connect
    conn = _connect(dsn, connection_factory=connection_factory, **kwasync)
psycopg2.OperationalError: FATAL:  could not open file "global/pg_filenode.map": Permission denied


The above exception was the direct cause of the following exception:

Traceback (most recent call last):
  File "/usr/local/lib/python3.8/dist-packages/airflow/dag_processing/processor.py", line 164, in _run_file_processor
    result: Tuple[int, int] = dag_file_processor.process_file(
  File "/usr/local/lib/python3.8/dist-packages/airflow/utils/session.py", line 70, in wrapper
    return func(*args, session=session, **kwargs)
  File "/usr/local/lib/python3.8/dist-packages/airflow/dag_processing/processor.py", line 632, in process_file
    dagbag.sync_to_db()
  File "/usr/local/lib/python3.8/dist-packages/airflow/utils/session.py", line 70, in wrapper
    return func(*args, session=session, **kwargs)
  File "/usr/local/lib/python3.8/dist-packages/airflow/models/dagbag.py", line 604, in sync_to_db
    for attempt in run_with_db_retries(logger=self.log):
  File "/usr/local/lib/python3.8/dist-packages/tenacity/__init__.py", line 390, in __iter__
    do = self.iter(retry_state=retry_state)
  File "/usr/local/lib/python3.8/dist-packages/tenacity/__init__.py", line 368, in iter
    raise retry_exc.reraise()
  File "/usr/local/lib/python3.8/dist-packages/tenacity/__init__.py", line 186, in reraise
    raise self.last_attempt.result()
  File "/usr/lib/python3.8/concurrent/futures/_base.py", line 437, in result
    return self.__get_result()
  File "/usr/lib/python3.8/concurrent/futures/_base.py", line 389, in __get_result
    raise self._exception
  File "/usr/local/lib/python3.8/dist-packages/airflow/models/dagbag.py", line 616, in sync_to_db
    serialize_errors.extend(_serialize_dag_capturing_errors(dag, session))
  File "/usr/local/lib/python3.8/dist-packages/airflow/models/dagbag.py", line 587, in _serialize_dag_capturing_errors
    dag_was_updated = SerializedDagModel.write_dag(
  File "/usr/local/lib/python3.8/dist-packages/airflow/utils/session.py", line 67, in wrapper
    return func(*args, **kwargs)
  File "/usr/local/lib/python3.8/dist-packages/airflow/models/serialized_dag.py", line 120, in write_dag
    if session.query(
  File "/usr/local/lib/python3.8/dist-packages/sqlalchemy/orm/query.py", line 3523, in scalar
    ret = self.one()
  File "/usr/local/lib/python3.8/dist-packages/sqlalchemy/orm/query.py", line 3490, in one
    ret = self.one_or_none()
  File "/usr/local/lib/python3.8/dist-packages/sqlalchemy/orm/query.py", line 3459, in one_or_none
    ret = list(self)
  File "/usr/local/lib/python3.8/dist-packages/sqlalchemy/orm/query.py", line 3535, in __iter__
    return self._execute_and_instances(context)
  File "/usr/local/lib/python3.8/dist-packages/sqlalchemy/orm/query.py", line 3556, in _execute_and_instances
    conn = self._get_bind_args(
  File "/usr/local/lib/python3.8/dist-packages/sqlalchemy/orm/query.py", line 3571, in _get_bind_args
    return fn(
  File "/usr/local/lib/python3.8/dist-packages/sqlalchemy/orm/query.py", line 3550, in _connection_from_session
    conn = self.session.connection(**kw)
  File "/usr/local/lib/python3.8/dist-packages/sqlalchemy/orm/session.py", line 1142, in connection
    return self._connection_for_bind(
  File "/usr/local/lib/python3.8/dist-packages/sqlalchemy/orm/session.py", line 1150, in _connection_for_bind
    return self.transaction._connection_for_bind(
  File "/usr/local/lib/python3.8/dist-packages/sqlalchemy/orm/session.py", line 433, in _connection_for_bind
    conn = bind._contextual_connect()
  File "/usr/local/lib/python3.8/dist-packages/sqlalchemy/engine/base.py", line 2302, in _contextual_connect
    self._wrap_pool_connect(self.pool.connect, None),
  File "/usr/local/lib/python3.8/dist-packages/sqlalchemy/engine/base.py", line 2339, in _wrap_pool_connect
    Connection._handle_dbapi_exception_noconnection(
  File "/usr/local/lib/python3.8/dist-packages/sqlalchemy/engine/base.py", line 1583, in _handle_dbapi_exception_noconnection
    util.raise_(
  File "/usr/local/lib/python3.8/dist-packages/sqlalchemy/util/compat.py", line 182, in raise_
    raise exception
  File "/usr/local/lib/python3.8/dist-packages/sqlalchemy/engine/base.py", line 2336, in _wrap_pool_connect
    return fn()
  File "/usr/local/lib/python3.8/dist-packages/sqlalchemy/pool/base.py", line 364, in connect
    return _ConnectionFairy._checkout(self)
  File "/usr/local/lib/python3.8/dist-packages/sqlalchemy/pool/base.py", line 778, in _checkout
    fairy = _ConnectionRecord.checkout(pool)
  File "/usr/local/lib/python3.8/dist-packages/sqlalchemy/pool/base.py", line 495, in checkout
    rec = pool._do_get()
  File "/usr/local/lib/python3.8/dist-packages/sqlalchemy/pool/impl.py", line 140, in _do_get
    self._dec_overflow()
  File "/usr/local/lib/python3.8/dist-packages/sqlalchemy/util/langhelpers.py", line 68, in __exit__
    compat.raise_(
  File "/usr/local/lib/python3.8/dist-packages/sqlalchemy/util/compat.py", line 182, in raise_
    raise exception
  File "/usr/local/lib/python3.8/dist-packages/sqlalchemy/pool/impl.py", line 137, in _do_get
    return self._create_connection()
  File "/usr/local/lib/python3.8/dist-packages/sqlalchemy/pool/base.py", line 309, in _create_connection
    return _ConnectionRecord(self)
  File "/usr/local/lib/python3.8/dist-packages/sqlalchemy/pool/base.py", line 440, in __init__
    self.__connect(first_connect_check=True)
  File "/usr/local/lib/python3.8/dist-packages/sqlalchemy/pool/base.py", line 661, in __connect
    pool.logger.debug("Error on connect(): %s", e)
  File "/usr/local/lib/python3.8/dist-packages/sqlalchemy/util/langhelpers.py", line 68, in __exit__
    compat.raise_(
  File "/usr/local/lib/python3.8/dist-packages/sqlalchemy/util/compat.py", line 182, in raise_
    raise exception
  File "/usr/local/lib/python3.8/dist-packages/sqlalchemy/pool/base.py", line 656, in __connect
    connection = pool._invoke_creator(self)
  File "/usr/local/lib/python3.8/dist-packages/sqlalchemy/engine/strategies.py", line 114, in connect
    return dialect.connect(*cargs, **cparams)
  File "/usr/local/lib/python3.8/dist-packages/sqlalchemy/engine/default.py", line 508, in connect
    return self.dbapi.connect(*cargs, **cparams)
  File "/usr/local/lib/python3.8/dist-packages/psycopg2/__init__.py", line 122, in connect
    conn = _connect(dsn, connection_factory=connection_factory, **kwasync)
sqlalchemy.exc.OperationalError: (psycopg2.OperationalError) FATAL:  could not open file "global/pg_filenode.map": Permission denied

(Background on this error at: http://sqlalche.me/e/13/e3q8)
[2021-09-03 04:05:30,782] {processor.py:162} INFO - Started process (PID=402) to work on /usr/local/airflow/dags/__pycache__/mssqlToCSV.py
[2021-09-03 04:05:30,783] {processor.py:613} INFO - Processing file /usr/local/airflow/dags/__pycache__/mssqlToCSV.py for tasks to queue
[2021-09-03 04:05:30,784] {logging_mixin.py:109} INFO - [2021-09-03 04:05:30,784] {dagbag.py:496} INFO - Filling up the DagBag from /usr/local/airflow/dags/__pycache__/mssqlToCSV.py
[2021-09-03 04:05:30,803] {processor.py:623} INFO - DAG(s) dict_keys(['mssql_to_csv']) retrieved from /usr/local/airflow/dags/__pycache__/mssqlToCSV.py
[2021-09-03 04:05:31,417] {processor.py:173} ERROR - Got an exception! Propagating...
Traceback (most recent call last):
  File "/usr/local/lib/python3.8/dist-packages/sqlalchemy/engine/base.py", line 2336, in _wrap_pool_connect
    return fn()
  File "/usr/local/lib/python3.8/dist-packages/sqlalchemy/pool/base.py", line 364, in connect
    return _ConnectionFairy._checkout(self)
  File "/usr/local/lib/python3.8/dist-packages/sqlalchemy/pool/base.py", line 778, in _checkout
    fairy = _ConnectionRecord.checkout(pool)
  File "/usr/local/lib/python3.8/dist-packages/sqlalchemy/pool/base.py", line 495, in checkout
    rec = pool._do_get()
  File "/usr/local/lib/python3.8/dist-packages/sqlalchemy/pool/impl.py", line 140, in _do_get
    self._dec_overflow()
  File "/usr/local/lib/python3.8/dist-packages/sqlalchemy/util/langhelpers.py", line 68, in __exit__
    compat.raise_(
  File "/usr/local/lib/python3.8/dist-packages/sqlalchemy/util/compat.py", line 182, in raise_
    raise exception
  File "/usr/local/lib/python3.8/dist-packages/sqlalchemy/pool/impl.py", line 137, in _do_get
    return self._create_connection()
  File "/usr/local/lib/python3.8/dist-packages/sqlalchemy/pool/base.py", line 309, in _create_connection
    return _ConnectionRecord(self)
  File "/usr/local/lib/python3.8/dist-packages/sqlalchemy/pool/base.py", line 440, in __init__
    self.__connect(first_connect_check=True)
  File "/usr/local/lib/python3.8/dist-packages/sqlalchemy/pool/base.py", line 661, in __connect
    pool.logger.debug("Error on connect(): %s", e)
  File "/usr/local/lib/python3.8/dist-packages/sqlalchemy/util/langhelpers.py", line 68, in __exit__
    compat.raise_(
  File "/usr/local/lib/python3.8/dist-packages/sqlalchemy/util/compat.py", line 182, in raise_
    raise exception
  File "/usr/local/lib/python3.8/dist-packages/sqlalchemy/pool/base.py", line 656, in __connect
    connection = pool._invoke_creator(self)
  File "/usr/local/lib/python3.8/dist-packages/sqlalchemy/engine/strategies.py", line 114, in connect
    return dialect.connect(*cargs, **cparams)
  File "/usr/local/lib/python3.8/dist-packages/sqlalchemy/engine/default.py", line 508, in connect
    return self.dbapi.connect(*cargs, **cparams)
  File "/usr/local/lib/python3.8/dist-packages/psycopg2/__init__.py", line 122, in connect
    conn = _connect(dsn, connection_factory=connection_factory, **kwasync)
psycopg2.OperationalError: FATAL:  could not open file "global/pg_filenode.map": Permission denied


The above exception was the direct cause of the following exception:

Traceback (most recent call last):
  File "/usr/local/lib/python3.8/dist-packages/airflow/dag_processing/processor.py", line 164, in _run_file_processor
    result: Tuple[int, int] = dag_file_processor.process_file(
  File "/usr/local/lib/python3.8/dist-packages/airflow/utils/session.py", line 70, in wrapper
    return func(*args, session=session, **kwargs)
  File "/usr/local/lib/python3.8/dist-packages/airflow/dag_processing/processor.py", line 632, in process_file
    dagbag.sync_to_db()
  File "/usr/local/lib/python3.8/dist-packages/airflow/utils/session.py", line 70, in wrapper
    return func(*args, session=session, **kwargs)
  File "/usr/local/lib/python3.8/dist-packages/airflow/models/dagbag.py", line 604, in sync_to_db
    for attempt in run_with_db_retries(logger=self.log):
  File "/usr/local/lib/python3.8/dist-packages/tenacity/__init__.py", line 390, in __iter__
    do = self.iter(retry_state=retry_state)
  File "/usr/local/lib/python3.8/dist-packages/tenacity/__init__.py", line 368, in iter
    raise retry_exc.reraise()
  File "/usr/local/lib/python3.8/dist-packages/tenacity/__init__.py", line 186, in reraise
    raise self.last_attempt.result()
  File "/usr/lib/python3.8/concurrent/futures/_base.py", line 437, in result
    return self.__get_result()
  File "/usr/lib/python3.8/concurrent/futures/_base.py", line 389, in __get_result
    raise self._exception
  File "/usr/local/lib/python3.8/dist-packages/airflow/models/dagbag.py", line 616, in sync_to_db
    serialize_errors.extend(_serialize_dag_capturing_errors(dag, session))
  File "/usr/local/lib/python3.8/dist-packages/airflow/models/dagbag.py", line 587, in _serialize_dag_capturing_errors
    dag_was_updated = SerializedDagModel.write_dag(
  File "/usr/local/lib/python3.8/dist-packages/airflow/utils/session.py", line 67, in wrapper
    return func(*args, **kwargs)
  File "/usr/local/lib/python3.8/dist-packages/airflow/models/serialized_dag.py", line 120, in write_dag
    if session.query(
  File "/usr/local/lib/python3.8/dist-packages/sqlalchemy/orm/query.py", line 3523, in scalar
    ret = self.one()
  File "/usr/local/lib/python3.8/dist-packages/sqlalchemy/orm/query.py", line 3490, in one
    ret = self.one_or_none()
  File "/usr/local/lib/python3.8/dist-packages/sqlalchemy/orm/query.py", line 3459, in one_or_none
    ret = list(self)
  File "/usr/local/lib/python3.8/dist-packages/sqlalchemy/orm/query.py", line 3535, in __iter__
    return self._execute_and_instances(context)
  File "/usr/local/lib/python3.8/dist-packages/sqlalchemy/orm/query.py", line 3556, in _execute_and_instances
    conn = self._get_bind_args(
  File "/usr/local/lib/python3.8/dist-packages/sqlalchemy/orm/query.py", line 3571, in _get_bind_args
    return fn(
  File "/usr/local/lib/python3.8/dist-packages/sqlalchemy/orm/query.py", line 3550, in _connection_from_session
    conn = self.session.connection(**kw)
  File "/usr/local/lib/python3.8/dist-packages/sqlalchemy/orm/session.py", line 1142, in connection
    return self._connection_for_bind(
  File "/usr/local/lib/python3.8/dist-packages/sqlalchemy/orm/session.py", line 1150, in _connection_for_bind
    return self.transaction._connection_for_bind(
  File "/usr/local/lib/python3.8/dist-packages/sqlalchemy/orm/session.py", line 433, in _connection_for_bind
    conn = bind._contextual_connect()
  File "/usr/local/lib/python3.8/dist-packages/sqlalchemy/engine/base.py", line 2302, in _contextual_connect
    self._wrap_pool_connect(self.pool.connect, None),
  File "/usr/local/lib/python3.8/dist-packages/sqlalchemy/engine/base.py", line 2339, in _wrap_pool_connect
    Connection._handle_dbapi_exception_noconnection(
  File "/usr/local/lib/python3.8/dist-packages/sqlalchemy/engine/base.py", line 1583, in _handle_dbapi_exception_noconnection
    util.raise_(
  File "/usr/local/lib/python3.8/dist-packages/sqlalchemy/util/compat.py", line 182, in raise_
    raise exception
  File "/usr/local/lib/python3.8/dist-packages/sqlalchemy/engine/base.py", line 2336, in _wrap_pool_connect
    return fn()
  File "/usr/local/lib/python3.8/dist-packages/sqlalchemy/pool/base.py", line 364, in connect
    return _ConnectionFairy._checkout(self)
  File "/usr/local/lib/python3.8/dist-packages/sqlalchemy/pool/base.py", line 778, in _checkout
    fairy = _ConnectionRecord.checkout(pool)
  File "/usr/local/lib/python3.8/dist-packages/sqlalchemy/pool/base.py", line 495, in checkout
    rec = pool._do_get()
  File "/usr/local/lib/python3.8/dist-packages/sqlalchemy/pool/impl.py", line 140, in _do_get
    self._dec_overflow()
  File "/usr/local/lib/python3.8/dist-packages/sqlalchemy/util/langhelpers.py", line 68, in __exit__
    compat.raise_(
  File "/usr/local/lib/python3.8/dist-packages/sqlalchemy/util/compat.py", line 182, in raise_
    raise exception
  File "/usr/local/lib/python3.8/dist-packages/sqlalchemy/pool/impl.py", line 137, in _do_get
    return self._create_connection()
  File "/usr/local/lib/python3.8/dist-packages/sqlalchemy/pool/base.py", line 309, in _create_connection
    return _ConnectionRecord(self)
  File "/usr/local/lib/python3.8/dist-packages/sqlalchemy/pool/base.py", line 440, in __init__
    self.__connect(first_connect_check=True)
  File "/usr/local/lib/python3.8/dist-packages/sqlalchemy/pool/base.py", line 661, in __connect
    pool.logger.debug("Error on connect(): %s", e)
  File "/usr/local/lib/python3.8/dist-packages/sqlalchemy/util/langhelpers.py", line 68, in __exit__
    compat.raise_(
  File "/usr/local/lib/python3.8/dist-packages/sqlalchemy/util/compat.py", line 182, in raise_
    raise exception
  File "/usr/local/lib/python3.8/dist-packages/sqlalchemy/pool/base.py", line 656, in __connect
    connection = pool._invoke_creator(self)
  File "/usr/local/lib/python3.8/dist-packages/sqlalchemy/engine/strategies.py", line 114, in connect
    return dialect.connect(*cargs, **cparams)
  File "/usr/local/lib/python3.8/dist-packages/sqlalchemy/engine/default.py", line 508, in connect
    return self.dbapi.connect(*cargs, **cparams)
  File "/usr/local/lib/python3.8/dist-packages/psycopg2/__init__.py", line 122, in connect
    conn = _connect(dsn, connection_factory=connection_factory, **kwasync)
sqlalchemy.exc.OperationalError: (psycopg2.OperationalError) FATAL:  could not open file "global/pg_filenode.map": Permission denied

(Background on this error at: http://sqlalche.me/e/13/e3q8)
